Workbook
Name SegmentaçãodeDados_Área: #N/A
Name SegmentaçãodeDados_Coordenador: #N/A
Name SegmentaçãodeDados_Data: #N/A
Name SegmentaçãodeDados_Data1: #N/A
Name SegmentaçãodeDados_Data2: #N/A
Name SegmentaçãodeDados_Fila_de_Atendimento: #N/A
Name SegmentaçãodeDados_Fila_de_Atendimento1: #N/A
Name SegmentaçãodeDados_Nome: #N/A
Name SegmentaçãodeDados_Nome_Completo: #N/A
Name SegmentaçãodeDados_Nome_Completo1: #N/A
Name SegmentaçãodeDados_Supervisor: #N/A
Name SegmentaçãodeDados_Supervisor1: #N/A
Name SegmentaçãodeDados_Supervisor2: #N/A
Name SegmentaçãodeDados_Turno: #N/A

Sheet Painel
A1: PAINEL DE ANÁLISE — CHAMADAS, TMA E PAUSAS — HUBMAIS
A4: 🎛️ SEGMENTAÇÕES
A14: 📊 INDICADORES (apenas das linhas visíveis após filtro)
A15: Chamadas | D15: TMA Médio | G15: Tempo Total Falado | J15: Pausa Descanso | M15: Pausa Lanche | P15: Tempo Total Pausa | S15: % Pausa
A16: =SUBTOTAL(109,tblResultados[Chamadas]) -> 23493 | D16: =IFERROR(SUBTOTAL(109,tblResultados[Tempo Falado])/SUBTOTAL(109,tblResultados[Chamadas]),0) -> 0.0061196691 | G16: =SUBTOTAL(109,tblResultados[Tempo Falado]) -> 143.76939 | J16: =SUBTOTAL(109,tblResultados[DESCAN]) -> 21.277407 | M16: =SUBTOTAL(109,tblResultados[LANCHE]) -> 19.232407 | P16: =SUBTOTAL(109,tblResultados[Tempo Pausado]) -> 139.45679 | S16: =IFERROR(SUBTOTAL(109,tblResultados[Tempo Pausado])/SUBTOTAL(109,tblResultados[Tempo Logado]),0) -> 0.37581945
P18: ℹ % Pausa: inclui TODOS os agentes logados, mesmo quem não atendeu nenhuma chamada (por isso fica maior que na aba Análise por Fila).
A19: 📋 BASE DE DADOS (1 linha por agente × dia)
A20: Data | B20: Nome | C20: ID | D20: Supervisor | E20: Coordenador | F20: Área | G20: Turno | H20: Chamadas | I20: Tempo Logado | J20: Tempo Falado | K20: TMA | L20: Tempo Pausado | M20: Pausa % Login | N20: BANHEI | O20: DESCAN | P20: DISMX | Q20: FEEDBK | R20: LAGGED | S20: LANCHE | T20: LOGIN | U20: MANUAL | V20: TESTE | W20: TREINA
A21: 46235 | B21: ADRIAM DA CONCEICAO SILVA | C21: adriamsilva | D21: JENNYFER CABRERA DA CRUZ LIMA | E21: KARLA DAS DORES DE SOUSA | F21: BACKOFFICE | G21: VESPERTINO | H21: 0 | I21: 0.25207176 | J21: 0 | K21: =IFERROR(J21/H21,0) -> 0 | L21: 0.045925926 | M21: =IFERROR(L21/I21,0) -> 0.18219386 | N21: 0.01875 | O21: 0.0079513889 | S21: 0.01474537 | T21: 0.0044791667
A22: 46235 | B22: ALAINE BARBOSA RIBEIRO | C22: alaineribeiro | D22: RAFAEL ALVES DE LIMA | E22: BIANCA MUNIZ FERREIRA | F22: SAC | G22: MATUTINO | H22: 12 | I22: 0.25457176 | J22: 0.11768519 | K22: =IFERROR(J22/H22,0) -> 0.0098070988 | L22: 0.039803241 | M22: =IFERROR(L22/I22,0) -> 0.15635372 | N22: 0.0079398148 | O22: 0.013622685 | S22: 0.01431713 | T22: 0.0032407407 | U22: 0.00068287037
A23: 46235 | B23: ALEXANDRE LOPES DOS SANTOS | C23: alexandresantos | D23: REGINALDO SOUSA BARBOSA | E23: KARLA DAS DORES DE SOUSA | F23: COBRANCA | G23: VESPERTINO | H23: 8 | I23: 0.2575 | J23: 0.026770833 | K23: =IFERROR(J23/H23,0) -> 0.0033463542 | L23: 0.032025463 | M23: =IFERROR(L23/I23,0) -> 0.12437073 | N23: 0.0033564815 | O23: 0.013831019 | S23: 0.014340278 | T23: 0.00013888889 | U23: 0.00033564815
A24: 46235 | B24: AMANDA LORENA ALVES | C24: amandaalves | D24: RAFAEL ALVES DE LIMA | E24: BIANCA MUNIZ FERREIRA | F24: SAC | G24: MATUTINO | H24: 23 | I24: 0.25962963 | J24: 0.089826389 | K24: =IFERROR(J24/H24,0) -> 0.0039054952 | L24: 0.057037037 | M24: =IFERROR(L24/I24,0) -> 0.21968616 | O24: 0.0153125 | S24: 0.014803241 | T24: 0.014421296 | U24: 0.00041666667 | W24: 0.012048611
A25: 46235 | B25: ANANDA SANTOS VIEIRA | C25: anandavieira | D25: RAFAEL ALVES DE LIMA | E25: BIANCA MUNIZ FERREIRA | F25: SAC | G25: MATUTINO | H25: 23 | I25: 0.27071759 | J25: 0.059143519 | K25: =IFERROR(J25/H25,0) -> 0.0025714573 | L25: 0.043402778 | M25: =IFERROR(L25/I25,0) -> 0.16032493 | N25: 0.007337963 | O25: 0.0071296296 | R25: 0.007650463 | S25: 0.01494213 | T25: 0.0055439815 | U25: 0.00023148148
A26: 46235 | B26: ANDRESSA PEREIRA DOS SANTOS | C26: andressasantos | D26: RAFAEL ALVES DE LIMA | E26: BIANCA MUNIZ FERREIRA | F26: SAC | G26: MATUTINO | H26: 24 | I26: 0.25571759 | J26: 0.078842593 | K26: =IFERROR(J26/H26,0) -> 0.003285108 | L26: 0.039421296 | M26: =IFERROR(L26/I26,0) -> 0.1541595 | N26: 0.003287037 | O26: 0.013287037 | S26: 0.013715278 | T26: 0.0069675926 | U26: 0.0021643519
A27: 46235 | B27: ARIENE GONCALVES DE MORAES NASCIMENTO | C27: arienenascimento | D27: RAFAEL ALVES DE LIMA | E27: BIANCA MUNIZ FERREIRA | F27: SAC | G27: MATUTINO | H27: 3 | I27: 0.14228009 | J27: 0.013587963 | K27: =IFERROR(J27/H27,0) -> 0.004529321 | L27: 0.10108796 | M27: =IFERROR(L27/I27,0) -> 0.71048564 | N27: 0.0056018519 | O27: 0.012002315 | T27: 0.04375 | U27: 0.00032407407 | W27: 0.039409722
A28: 46235 | B28: BARBARA GLENDA DONIZETE DIAS | C28: barbaradias | D28: RAFAEL ALVES DE LIMA | E28: BIANCA MUNIZ FERREIRA | F28: SAC | G28: MATUTINO | H28: 3 | I28: 0.2259838 | J28: 0.0077546296 | K28: =IFERROR(J28/H28,0) -> 0.0025848765 | L28: 0.20126157 | M28: =IFERROR(L28/I28,0) -> 0.89060179 | O28: 0.0059606481 | S28: 0.012893519 | T28: 0.00048611111 | W28: 0.1819213
A29: 46235 | B29: BRENDO ARAUJO DA LUZ | C29: brendoluz | D29: NICOLAS NOLBERTO MENA | E29: BIANCA MUNIZ FERREIRA | F29: RETENCAO | G29: VESPERTINO | H29: 8 | I29: 0.25012731 | J29: 0.057731481 | K29: =IFERROR(J29/H29,0) -> 0.0072164352 | L29: 0.12460648 | M29: =IFERROR(L29/I29,0) -> 0.49817223 | O29: 0.015081019 | Q29: 0.021631944 | S29: 0.014016204 | T29: 0.00046296296 | U29: 0.025046296 | W29: 0.048368056
A30: 46235 | B30: CAMILA OLIVEIRA DAS CHAGAS | C30: camilachagas | D30: NICOLAS NOLBERTO MENA | E30: BIANCA MUNIZ FERREIRA | F30: RETENCAO | G30: VESPERTINO | H30: 7 | I30: 0.24979167 | J30: 0.035069444 | K30: =IFERROR(J30/H30,0) -> 0.0050099206 | L30: 0.11475694 | M30: =IFERROR(L30/I30,0) -> 0.45941062 | N30: 0.0086921296 | O30: 0.0196875 | Q30: 0.017974537 | S30: 0.043159722 | T30: 0.00017361111 | U30: 0.0016898148 | W30: 0.023356481
A31: 46235 | B31: CARLA RAYNARA CAMPELO COSTA | C31: carlacampelo | D31: PAULA FERNANDA ALVES | E31: KARLA DAS DORES DE SOUSA | F31: COBRANCA | G31: MATUTINO | H31: 19 | I31: 0.26445602 | J31: 0.029166667 | K31: =IFERROR(J31/H31,0) -> 0.0015350877 | L31: 0.046377315 | M31: =IFERROR(L31/I31,0) -> 0.17536873 | N31: 0.0052546296 | O31: 0.014768519 | Q31: 0.0099421296 | S31: 0.016018519 | T31: 0.00011574074 | U31: 4.6296296e-05 | W31: 0.00021990741
A32: 46235 | B32: DAIANE FERREIRA DA SILVA | C32: daianesilva | D32: PAULA FERNANDA ALVES | E32: KARLA DAS DORES DE SOUSA | F32: COBRANCA | G32: MATUTINO | H32: 19 | I32: 0.26240741 | J32: 0.031678241 | K32: =IFERROR(J32/H32,0) -> 0.0016672758 | L32: 0.05837963 | M32: =IFERROR(L32/I32,0) -> 0.22247706 | N32: 0.0026273148 | O32: 0.010868056 | Q32: 0.029305556 | S32: 0.01443287 | T32: 0.00016203704 | U32: 0.00090277778
A33: 46235 | B33: DANDARA MONTEIRO OLIVEIRA | C33: dandaraoliveira | D33: MARCOS VINICIUS ALVES DE OLIVEIRA | E33: BIANCA MUNIZ FERREIRA | F33: RETENCAO | G33: MATUTINO | H33: 7 | I33: 0.23166667 | J33: 0.12538194 | K33: =IFERROR(J33/H33,0) -> 0.017911706 | L33: 0.10849537 | M33: =IFERROR(L33/I33,0) -> 0.46832534 | N33: 0.033553241 | O33: 0.016354167 | S33: 0.013865741 | T33: 0.00020833333 | U33: 0.009849537 | W33: 0.034664352
A34: 46235 | B34: DANILLO BARBOSA OLIVEIRA | C34: danillooliveira | D34: MARCOS VINICIUS ALVES DE OLIVEIRA | E34: BIANCA MUNIZ FERREIRA | F34: RETENCAO | G34: MATUTINO | H34: 19 | I34: 0.25931713 | J34: 0.19207176 | K34: =IFERROR(J34/H34,0) -> 0.01010904 | L34: 0.069826389 | M34: =IFERROR(L34/I34,0) -> 0.26927025 | N34: 0.014560185 | O34: 0.013900463 | R34: 4.6296296e-05 | S34: 0.013391204 | T34: 0.0009837963 | U34: 0.0014583333 | W34: 0.025474537
A35: 46235 | B35: DEBORA BRAGA DE MATOS AQUINO | C35: deboraaquino | D35: MARCOS VINICIUS ALVES DE OLIVEIRA | E35: BIANCA MUNIZ FERREIRA | F35: RETENCAO | G35: MATUTINO | H35: 16 | I35: 0.27681713 | J35: 0.13174769 | K35: =IFERROR(J35/H35,0) -> 0.0082342303 | L35: 0.12961806 | M35: =IFERROR(L35/I35,0) -> 0.46824435 | N35: 0.011770833 | O35: 0.014872685 | S35: 0.014953704 | T35: 0.072824074 | U35: 0.0010763889 | W35: 0.01412037
A36: 46235 | B36: DEBORA DA SILVA COELHO | C36: deboracoelho | D36: RENATA MARQUES LIMA DOS REIS | E36: BIANCA MUNIZ FERREIRA | F36: SAC | G36: VESPERTINO | H36: 17 | I36: 0.2478125 | J36: 0.10821759 | K36: =IFERROR(J36/H36,0) -> 0.0063657407 | L36: 0.029930556 | M36: =IFERROR(L36/I36,0) -> 0.12077904 | O36: 0.0070717593 | R36: 0.0070949074 | S36: 0.014212963 | T36: 0.00052083333 | U36: 0.00096064815
A37: 46235 | B37: DIOVANIA ROCHA ALVES SANTOS | C37: diovaniasantos | D37: RAFAEL ALVES DE LIMA | E37: BIANCA MUNIZ FERREIRA | F37: SAC | G37: MATUTINO | H37: 2 | I37: 0.21841435 | J37: 0.0098842593 | K37: =IFERROR(J37/H37,0) -> 0.0049421296 | L37: 0.19186343 | M37: =IFERROR(L37/I37,0) -> 0.87843781 | N37: 0.015509259 | O37: 0.013287037 | S37: 0.013935185 | T37: 0.00053240741 | W37: 0.14859954
A38: 46235 | B38: EDUARDO BARBOSA MARQUES | C38: eduardomarques | D38: PAULA FERNANDA ALVES | E38: KARLA DAS DORES DE SOUSA | F38: COBRANCA | G38: MATUTINO | H38: 13 | I38: 0.2575463 | J38: 0.0096875 | K38: =IFERROR(J38/H38,0) -> 0.00074519231 | L38: 0.059363426 | M38: =IFERROR(L38/I38,0) -> 0.23049614 | N38: 0.007662037 | O38: 0.014548611 | Q38: 0.016145833 | S38: 0.014861111 | T38: 8.1018519e-05 | U38: 0.0056944444
A39: 46235 | B39: EDUARDO GABRIEL ANGELIM GONCALVES | C39: eduardogoncalves | D39: RENATA MARQUES LIMA DOS REIS | E39: BIANCA MUNIZ FERREIRA | F39: SAC | G39: VESPERTINO | H39: 14 | I39: 0.23895833 | J39: 0.058483796 | K39: =IFERROR(J39/H39,0) -> 0.004177414 | L39: 0.028680556 | M39: =IFERROR(L39/I39,0) -> 0.12002325 | N39: 0.0078009259 | O39: 0.014282407 | T39: 0.00071759259 | U39: 0.00087962963 | W39: 0.0049421296
A40: 46235 | B40: EDYNAYANE LIMA DE FRANCA | C40: edynayanefranca | D40: RAFAEL ALVES DE LIMA | E40: BIANCA MUNIZ FERREIRA | F40: SAC | G40: MATUTINO | H40: 19 | I40: 0.26371528 | J40: 0.074618056 | K40: =IFERROR(J40/H40,0) -> 0.0039272661 | L40: 0.058541667 | M40: =IFERROR(L40/I40,0) -> 0.22198815 | N40: 0.011076389 | O40: 0.013842593 | S40: 0.01462963 | T40: 0.017384259 | U40: 0.0015393519 | W40: 6.9444444e-05
A41: 46235 | B41: ELAINE OLIVEIRA SILVA | C41: elainesilva | D41: RENATA MARQUES LIMA DOS REIS | E41: BIANCA MUNIZ FERREIRA | F41: SAC | G41: VESPERTINO | H41: 17 | I41: 0.25762731 | J41: 0.094918981 | K41: =IFERROR(J41/H41,0) -> 0.0055834695 | L41: 0.032650463 | M41: =IFERROR(L41/I41,0) -> 0.12673525 | N41: 0.0016087963 | O41: 0.014016204 | S41: 0.014502315 | T41: 0.00015046296 | U41: 0.00079861111 | W41: 0.0015625
A42: 46235 | B42: FABIO BORGES DOS SANTOS FILHO | C42: fabiofilho | D42: MARCOS VINICIUS ALVES DE OLIVEIRA | E42: BIANCA MUNIZ FERREIRA | F42: RETENCAO | G42: MATUTINO | H42: 10 | I42: 0.24667824 | J42: 0.098680556 | K42: =IFERROR(J42/H42,0) -> 0.0098680556 | L42: 0.11300926 | M42: =IFERROR(L42/I42,0) -> 0.45812415 | N42: 0.020219907 | O42: 0.0209375 | S42: 0.017534722 | T42: 0.0016435185 | U42: 0.0040393519 | W42: 0.048622685
A43: 46235 | B43: GABRIELA PIRES DOS SANTOS | C43: gabrielasantos | D43: PAULA FERNANDA ALVES | E43: KARLA DAS DORES DE SOUSA | F43: COBRANCA | G43: MATUTINO | H43: 9 | I43: 0.26329861 | J43: 0.051967593 | K43: =IFERROR(J43/H43,0) -> 0.005774177 | L43: 0.069143519 | M43: =IFERROR(L43/I43,0) -> 0.26260495 | N43: 0.0090393519 | O43: 0.014340278 | P43: 0.0017013889 | Q43: 0.027488426 | S43: 0.013773148 | T43: 0.00094907407 | U43: 0.0018171296
A44: 46235 | B44: GEOVANA DANIELE PINTO DAS NEVES | C44: geovananeves | D44: RAFAEL ALVES DE LIMA | E44: BIANCA MUNIZ FERREIRA | F44: SAC | G44: MATUTINO | H44: 29 | I44: 0.26295139 | J44: 0.097453704 | K44: =IFERROR(J44/H44,0) -> 0.0033604725 | L44: 0.026875 | M44: =IFERROR(L44/I44,0) -> 0.1022052 | N44: 0.0045949074 | O44: 0.0071064815 | Q44: 0.00074074074 | S44: 0.014027778 | T44: 8.1018519e-05 | U44: 0.0003125
A45: 46235 | B45: GEOVANA GABRIELLY QUEIROZ DOS SANTOS | C45: geovanasantos | D45: MARCOS VINICIUS ALVES DE OLIVEIRA | E45: BIANCA MUNIZ FERREIRA | F45: RETENCAO | G45: MATUTINO | H45: 7 | I45: 0.26298611 | J45: 0.16091435 | K45: =IFERROR(J45/H45,0) -> 0.022987765 | L45: 0.10422454 | M45: =IFERROR(L45/I45,0) -> 0.39631194 | N45: 0.0042592593 | O45: 0.013842593 | S45: 0.014525463 | T45: 5.787037e-05 | U45: 0.018831019 | W45: 0.052708333
A46: 46235 | B46: GERLAINY CRISTINA DE OLIVEIRA SANTOS | C46: gerlainysantos | D46: RENATA MARQUES LIMA DOS REIS | E46: BIANCA MUNIZ FERREIRA | F46: SAC | G46: VESPERTINO | H46: 12 | I46: 0.24902778 | J46: 0.11121528 | K46: =IFERROR(J46/H46,0) -> 0.0092679398 | L46: 0.03900463 | M46: =IFERROR(L46/I46,0) -> 0.15662763 | N46: 0.0046412037 | O46: 0.019050926 | S46: 0.014490741 | T46: 0.00025462963 | U46: 0.00032407407
A47: 46235 | B47: GILIELLE MAIANE ROSA E SILVA | C47: giliellesilva | D47: RAFAEL ALVES DE LIMA | E47: BIANCA MUNIZ FERREIRA | F47: SAC | G47: MATUTINO | H47: 19 | I47: 0.2637037 | J47: 0.062511574 | K47: =IFERROR(J47/H47,0) -> 0.0032900828 | L47: 0.063715278 | M47: =IFERROR(L47/I47,0) -> 0.24161692 | N47: 0.016770833 | O47: 0.016342593 | S47: 0.017002315 | T47: 0.013599537
A48: 46235 | B48: GUSTAVO PEREIRA TEIXEIRA | C48: gustavoteixeira | D48: RENATA MARQUES LIMA DOS REIS | E48: BIANCA MUNIZ FERREIRA | F48: SAC | G48: VESPERTINO | H48: 0 | I48: 0.14112269 | J48: 0 | K48: =IFERROR(J48/H48,0) -> 0 | L48: 0.14112269 | M48: =IFERROR(L48/I48,0) -> 1 | N48: 0.014189815 | O48: 0.0077199074 | Q48: 0.0048032407 | S48: 0.0060416667 | T48: 0.00040509259 | W48: 0.10796296
A49: 46235 | B49: HELENA VITORIA MACEDO DUTRA | C49: helenadutra | D49: RAFAEL ALVES DE LIMA | E49: BIANCA MUNIZ FERREIRA | F49: SAC | G49: MATUTINO | H49: 24 | I49: 0.26293981 | J49: 0.097673611 | K49: =IFERROR(J49/H49,0) -> 0.0040697338 | L49: 0.0018518519 | M49: =IFERROR(L49/I49,0) -> 0.0070428735 | T49: 9.2592593e-05 | U49: 0.0016782407 | W49: 1.1574074e-05
A50: 46235 | B50: IASMYM RIBEIRO DA SILVA | C50: iasmymsilva | D50: MARCOS VINICIUS ALVES DE OLIVEIRA | E50: BIANCA MUNIZ FERREIRA | F50: RETENCAO | G50: MATUTINO | H50: 16 | I50: 0.25856481 | J50: 0.18454861 | K50: =IFERROR(J50/H50,0) -> 0.011534288 | L50: 0.080497685 | M50: =IFERROR(L50/I50,0) -> 0.31132498 | N50: 0.02193287 | O50: 0.0099652778 | S50: 0.014212963 | T50: 9.2592593e-05 | U50: 0.01037037 | W50: 0.023888889
A51: 46235 | B51: ISABELA MENDES DAS NEVES | C51: isabelaneves | D51: JENNYFER CABRERA DA CRUZ LIMA | E51: KARLA DAS DORES DE SOUSA | F51: BACKOFFICE | G51: INTEGRAL | H51: 0 | I51: 0.0013541667 | J51: 0 | K51: =IFERROR(J51/H51,0) -> 0 | L51: 0 | M51: =IFERROR(L51/I51,0) -> 0
A52: 46235 | B52: IVONEIDE DUARTE FERREIRA | C52: ivoneideferreira | D52: REGINALDO SOUSA BARBOSA | E52: KARLA DAS DORES DE SOUSA | F52: COBRANCA | G52: VESPERTINO | H52: 12 | I52: 0.26288194 | J52: 0.036585648 | K52: =IFERROR(J52/H52,0) -> 0.003048804 | L52: 0.030266204 | M52: =IFERROR(L52/I52,0) -> 0.1151323 | N52: 0.0015162037 | O52: 0.013981481 | S52: 0.013981481 | T52: 0.00017361111 | U52: 0.00060185185
...

Sheet Análise por Fila
A1: ANÁLISE POR FILA DE ATENDIMENTO — HUBMAIS
A4: SEGMENTAÇÕES
A14: INDICADORES (apenas das linhas visíveis após filtro)
A15: Chamadas | C15: TMA Médio | E15: Tempo Total Falado | G15: Tempo Total Pausa | I15: % Pausa
A16: =SUBTOTAL(109,tblAnaliseFila[Chamadas]) -> 23493 | C16: =IFERROR(SUBTOTAL(109,tblAnaliseFila[Tempo Falado])/SUBTOTAL(109,tblAnaliseFila[Chamadas]),0) -> 0.0061196691 | E16: =SUBTOTAL(109,tblAnaliseFila[Tempo Falado]) -> 143.76939 | G16: =SUBTOTAL(109,tblAnaliseFila[Pausa]) -> 142.40293 | I16: =IFERROR(SUBTOTAL(109,tblAnaliseFila[Pausa])/SUBTOTAL(109,tblAnaliseFila[Tempo Logado]),0) -> 0.34990572
E18: ℹ % Pausa: considera só quem atendeu chamada (1 linha por agente × fila); quem logou e não atendeu não entra aqui (por isso fica menor que no Painel).
A19: BASE DE DADOS (1 linha por agente × fila × dia)
A20: Data | B20: Fila de Atendimento | C20: Agente | D20: Área Fixa (Escala) | E20: Chamadas | F20: Tempo Falado | G20: TMA | H20: Tempo Logado | I20: Pausa | J20: % Pausa | K20: Nome Completo | L20: Supervisor
A21: 46235 | B21: COBRANCA | C21: alexandresantos | D21: COBRANCA | E21: 4 | F21: 0.0071875 | G21: 0.001796875 | H21: 0.069134241 | I21: 0.008598276 | J21: 0.12437073 | K21: ALEXANDRE LOPES DOS SANTOS | L21: REGINALDO SOUSA BARBOSA
A22: 46235 | B22: COBRANCA | C22: carlacampelo | D22: COBRANCA | E22: 12 | F22: 0.020162037 | G22: 0.0016801698 | H22: 0.18281047 | I22: 0.032059239 | J22: 0.17536873 | K22: CARLA RAYNARA CAMPELO COSTA | L22: PAULA FERNANDA ALVES
A23: 46235 | B23: COBRANCA | C23: daianesilva | D23: COBRANCA | E23: 13 | F23: 0.019143519 | G23: 0.0014725783 | H23: 0.15857576 | I23: 0.035279469 | J23: 0.22247706 | K23: DAIANE FERREIRA DA SILVA | L23: PAULA FERNANDA ALVES
A24: 46235 | B24: COBRANCA | C24: eduardomarques | D24: COBRANCA | E24: 10 | F24: 0.0067361111 | G24: 0.00067361111 | H24: 0.17908237 | I24: 0.041277794 | J24: 0.23049614 | K24: EDUARDO BARBOSA MARQUES | L24: PAULA FERNANDA ALVES
A25: 46235 | B25: COBRANCA | C25: gabrielasantos | D25: COBRANCA | E25: 8 | F25: 0.051747685 | G25: 0.0064684606 | H25: 0.26218443 | I25: 0.068850929 | J25: 0.26260495 | K25: GABRIELA PIRES DOS SANTOS | L25: PAULA FERNANDA ALVES
A26: 46235 | B26: COBRANCA | C26: ivoneideferreira | D26: COBRANCA | E26: 10 | F26: 0.026018519 | G26: 0.0026018519 | H26: 0.18695306 | I26: 0.021524336 | J26: 0.1151323 | K26: IVONEIDE DUARTE FERREIRA | L26: REGINALDO SOUSA BARBOSA
A27: 46235 | B27: COBRANCA | C27: jeovannaferreira | D27: COBRANCA | E27: 9 | F27: 0.012905093 | G27: 0.0014338992 | H27: 0.095488491 | I27: 0.017159427 | J27: 0.17970152 | K27: JEOVANNA DE LIMA FERREIRA | L27: PAULA FERNANDA ALVES
A28: 46235 | B28: COBRANCA | C28: joaocruz | D28: COBRANCA | E28: 9 | F28: 0.020081019 | G28: 0.0022312243 | H28: 0.14380726 | I28: 0.025811061 | J28: 0.17948372 | K28: JOAO VITOR VIEIRA DA CRUZ | L28: PAULA FERNANDA ALVES
A29: 46235 | B29: COBRANCA | C29: joaosantos | D29: COBRANCA | E29: 7 | F29: 0.020231481 | G29: 0.0028902116 | H29: 0.14837095 | I29: 0.020495018 | J29: 0.13813362 | K29: JOAO PEDRO DE SOUZA SANTOS | L29: REGINALDO SOUSA BARBOSA
A30: 46235 | B30: COBRANCA | C30: kalissagoncalves | D30: COBRANCA | E30: 7 | F30: 0.012326389 | G30: 0.0017609127 | H30: 0.13074074 | I30: 0.020416667 | J30: 0.15616147 | K30: KALISSA VALERIO GONCALVES | L30: REGINALDO SOUSA BARBOSA
A31: 46235 | B31: COBRANCA | C31: karolynyassis | D31: COBRANCA | E31: 5 | F31: 0.025428241 | G31: 0.0050856481 | H31: 0.16946513 | I31: 0.038065353 | J31: 0.22462056 | K31: KAROLYNY KELLY OLIVEIRA ASSIS | L31: PAULA FERNANDA ALVES
A32: 46235 | B32: COBRANCA | C32: laissilva | D32: COBRANCA | E32: 8 | F32: 0.013703704 | G32: 0.001712963 | H32: 0.15025577 | I32: 0.03187045 | J32: 0.21210799 | K32: LAIS RIBEIRO DA SILVA | L32: PAULA FERNANDA ALVES
... A1811: 46253 | B1811: VENDAS | C1811: keythmorais | D1811: VENDAS | E1811: 45 | F1811: 0.077430556 | G1811: 0.001720679 | H1811: 0.24478009 | I1811: 0.10929398 | J1811: 0.44649865 | K1811: KEYTH RODRIGUES DE MORAIS | L1811: MARCOS VINICIUS ALVES DE OLIVEIRA

Sheet Atendimento Fila
A1: ATENDIMENTO POR FILA — HUBMAIS
A4: SEGMENTAÇÕES
A14: INDICADORES (apenas das linhas visíveis após filtro)
A15: Chamadas | D15: TMA Médio | F15: Tempo Total Falado
A16: =SUBTOTAL(109,tblFila[Chamadas]) -> 23493 | D16: =IFERROR(SUBTOTAL(109,tblFila[Tempo Falado])/SUBTOTAL(109,tblFila[Chamadas]),0) -> 0.0061196691 | F16: =SUBTOTAL(109,tblFila[Tempo Falado]) -> 143.76939
A19: BASE DE DADOS (1 linha por agente × fila × dia)
A20: Data | B20: Agente | C20: Área Fixa (Escala) | D20: Fila de Atendimento | E20: Chamadas | F20: Tempo Falado | G20: TMA | H20: Nome Completo | I20: Supervisor
A21: 46235 | B21: alaineribeiro | C21: SAC | D21: SAC | E21: 12 | F21: 0.11768519 | G21: 0.0098070988 | H21: ALAINE BARBOSA RIBEIRO | I21: RAFAEL ALVES DE LIMA
A22: 46235 | B22: alexandresantos | C22: COBRANCA | D22: COBRANCA | E22: 4 | F22: 0.0071875 | G22: 0.001796875 | H22: ALEXANDRE LOPES DOS SANTOS | I22: REGINALDO SOUSA BARBOSA
A23: 46235 | B23: alexandresantos | C23: COBRANCA | D23: SAC | E23: 4 | F23: 0.019583333 | G23: 0.0048958333 | H23: ALEXANDRE LOPES DOS SANTOS | I23: REGINALDO SOUSA BARBOSA
A24: 46235 | B24: amandaalves | C24: SAC | D24: SAC | E24: 23 | F24: 0.089826389 | G24: 0.0039054952 | H24: AMANDA LORENA ALVES | I24: RAFAEL ALVES DE LIMA
A25: 46235 | B25: anandavieira | C25: SAC | D25: SAC | E25: 23 | F25: 0.059143519 | G25: 0.0025714573 | H25: ANANDA SANTOS VIEIRA | I25: RAFAEL ALVES DE LIMA
A26: 46235 | B26: andressasantos | C26: SAC | D26: SAC | E26: 24 | F26: 0.078842593 | G26: 0.003285108 | H26: ANDRESSA PEREIRA DOS SANTOS | I26: RAFAEL ALVES DE LIMA
A27: 46235 | B27: arienenascimento | C27: SAC | D27: SAC | E27: 3 | F27: 0.013587963 | G27: 0.004529321 | H27: ARIENE GONCALVES DE MORAES NASCIMENTO | I27: RAFAEL ALVES DE LIMA
A28: 46235 | B28: barbaradias | C28: SAC | D28: SAC | E28: 3 | F28: 0.0077546296 | G28: 0.0025848765 | H28: BARBARA GLENDA DONIZETE DIAS | I28: RAFAEL ALVES DE LIMA
A29: 46235 | B29: brendoluz | C29: RETENCAO | D29: RETENCAO | E29: 8 | F29: 0.057731481 | G29: 0.0072164352 | H29: BRENDO ARAUJO DA LUZ | I29: NICOLAS NOLBERTO MENA
A30: 46235 | B30: camilachagas | C30: RETENCAO | D30: RETENCAO | E30: 7 | F30: 0.035069444 | G30: 0.0050099206 | H30: CAMILA OLIVEIRA DAS CHAGAS | I30: NICOLAS NOLBERTO MENA
A31: 46235 | B31: carlacampelo | C31: COBRANCA | D31: COBRANCA | E31: 12 | F31: 0.020162037 | G31: 0.0016801698 | H31: CARLA RAYNARA CAMPELO COSTA | I31: PAULA FERNANDA ALVES
A32: 46235 | B32: carlacampelo | C32: COBRANCA | D32: SAC | E32: 7 | F32: 0.0090046296 | G32: 0.0012863757 | H32: CARLA RAYNARA CAMPELO COSTA | I32: PAULA FERNANDA ALVES
... A1811: 46253 | B1811: yaraconceicao | C1811: COBRANCA | D1811: SAC | E1811: 8 | F1811: 0.021018519 | G1811: 0.0026273148 | H1811: YARA DO CARMO DA CONCEICAO | I1811: REGINALDO SOUSA BARBOSA

Sheet Visão Diária
A1: VISÃO DIÁRIA — EVOLUÇÃO DA OPERAÇÃO
A4: Data | B4: Dia da Semana | C4: # Agentes Ativos | D4: Chamadas | E4: Tempo Logado | F4: Tempo Falado | G4: TMA Médio | H4: Tempo Pausado | I4: Pausa % Login | J4: Logado/Agente | K4: Falado/Agente | L4: Pausado/Agente
A5: 46235 | B5: Sábado | C5: =COUNTIFS(Diário!$A:$A,A5) -> 90 | D5: =SUMIFS(Diário!$G:$G,Diário!$A:$A,A5) -> 1077 | E5: =SUMIFS(Diário!$H:$H,Diário!$A:$A,A5) -> 22.201887 | F5: =SUMIFS(Diário!$I:$I,Diário!$A:$A,A5) -> 6.9651736 | G5: =IFERROR(F5/D5,0) -> 0.0064671991 | H5: =SUMIFS(Diário!$K:$K,Diário!$A:$A,A5) -> 6.7243403 | I5: =IFERROR(H5/E5,0) -> 0.30287247 | J5: =IFERROR(E5/C5,0) -> 0.24668763 | K5: =IFERROR(F5/C5,0) -> 0.077390822 | L5: =IFERROR(H5/C5,0) -> 0.074714896
A6: 46237 | B6: Segunda | C6: =COUNTIFS(Diário!$A:$A,A6) -> 104 | D6: =SUMIFS(Diário!$G:$G,Diário!$A:$A,A6) -> 1829 | E6: =SUMIFS(Diário!$H:$H,Diário!$A:$A,A6) -> 27.122766 | F6: =SUMIFS(Diário!$I:$I,Diário!$A:$A,A6) -> 13.627407 | G6: =IFERROR(F6/D6,0) -> 0.0074507407 | H6: =SUMIFS(Diário!$K:$K,Diário!$A:$A,A6) -> 8.5208565 | I6: =IFERROR(H6/E6,0) -> 0.31415883 | J6: =IFERROR(E6/C6,0) -> 0.26079583 | K6: =IFERROR(F6/C6,0) -> 0.13103277 | L6: =IFERROR(H6/C6,0) -> 0.081931308
A7: 46238 | B7: Terça | C7: =COUNTIFS(Diário!$A:$A,A7) -> 107 | D7: =SUMIFS(Diário!$G:$G,Diário!$A:$A,A7) -> 1937 | E7: =SUMIFS(Diário!$H:$H,Diário!$A:$A,A7) -> 25.844178 | F7: =SUMIFS(Diário!$I:$I,Diário!$A:$A,A7) -> 13.427164 | G7: =IFERROR(F7/D7,0) -> 0.0069319329 | H7: =SUMIFS(Diário!$K:$K,Diário!$A:$A,A7) -> 9.6403704 | I7: =IFERROR(H7/E7,0) -> 0.37301903 | J7: =IFERROR(E7/C7,0) -> 0.24153437 | K7: =IFERROR(F7/C7,0) -> 0.12548751 | L7: =IFERROR(H7/C7,0) -> 0.090096921
A8: 46239 | B8: Quarta | C8: =COUNTIFS(Diário!$A:$A,A8) -> 107 | D8: =SUMIFS(Diário!$G:$G,Diário!$A:$A,A8) -> 1730 | E8: =SUMIFS(Diário!$H:$H,Diário!$A:$A,A8) -> 27.187025 | F8: =SUMIFS(Diário!$I:$I,Diário!$A:$A,A8) -> 13.533762 | G8: =IFERROR(F8/D8,0) -> 0.0078229861 | H8: =SUMIFS(Diário!$K:$K,Diário!$A:$A,A8) -> 8.9863657 | I8: =IFERROR(H8/E8,0) -> 0.33053876 | J8: =IFERROR(E8/C8,0) -> 0.25408435 | K8: =IFERROR(F8/C8,0) -> 0.12648375 | L8: =IFERROR(H8/C8,0) -> 0.083984722
A9: 46240 | B9: Quinta | C9: =COUNTIFS(Diário!$A:$A,A9) -> 106 | D9: =SUMIFS(Diário!$G:$G,Diário!$A:$A,A9) -> 1542 | E9: =SUMIFS(Diário!$H:$H,Diário!$A:$A,A9) -> 26.17728 | F9: =SUMIFS(Diário!$I:$I,Diário!$A:$A,A9) -> 10.376829 | G9: =IFERROR(F9/D9,0) -> 0.006729456 | H9: =SUMIFS(Diário!$K:$K,Diário!$A:$A,A9) -> 9.3818403 | I9: =IFERROR(H9/E9,0) -> 0.3583963 | J9: =IFERROR(E9/C9,0) -> 0.24695547 | K9: =IFERROR(F9/C9,0) -> 0.097894606 | L9: =IFERROR(H9/C9,0) -> 0.088507928
A10: 46241 | B10: Sexta | C10: =COUNTIFS(Diário!$A:$A,A10) -> 100 | D10: =SUMIFS(Diário!$G:$G,Diário!$A:$A,A10) -> 1385 | E10: =SUMIFS(Diário!$H:$H,Diário!$A:$A,A10) -> 24.520799 | F10: =SUMIFS(Diário!$I:$I,Diário!$A:$A,A10) -> 8.800463 | G10: =IFERROR(F10/D10,0) -> 0.0063541204 | H10: =SUMIFS(Diário!$K:$K,Diário!$A:$A,A10) -> 9.7510532 | I10: =IFERROR(H10/E10,0) -> 0.39766459 | J10: =IFERROR(E10/C10,0) -> 0.24520799 | K10: =IFERROR(F10/C10,0) -> 0.08800463 | L10: =IFERROR(H10/C10,0) -> 0.097510532
A11: 46242 | B11: Sábado | C11: =COUNTIFS(Diário!$A:$A,A11) -> 86 | D11: =SUMIFS(Diário!$G:$G,Diário!$A:$A,A11) -> 773 | E11: =SUMIFS(Diário!$H:$H,Diário!$A:$A,A11) -> 19.602072 | F11: =SUMIFS(Diário!$I:$I,Diário!$A:$A,A11) -> 4.1086806 | G11: =IFERROR(F11/D11,0) -> 0.0053152431 | H11: =SUMIFS(Diário!$K:$K,Diário!$A:$A,A11) -> 8.5507292 | I11: =IFERROR(H11/E11,0) -> 0.43621558 | J11: =IFERROR(E11/C11,0) -> 0.22793106 | K11: =IFERROR(F11/C11,0) -> 0.047775359 | L11: =IFERROR(H11/C11,0) -> 0.099427083
A12: 46244 | B12: Segunda | C12: =COUNTIFS(Diário!$A:$A,A12) -> 98 | D12: =SUMIFS(Diário!$G:$G,Diário!$A:$A,A12) -> 1544 | E12: =SUMIFS(Diário!$H:$H,Diário!$A:$A,A12) -> 24.774306 | F12: =SUMIFS(Diário!$I:$I,Diário!$A:$A,A12) -> 8.3757755 | G12: =IFERROR(F12/D12,0) -> 0.0054247222 | H12: =SUMIFS(Diário!$K:$K,Diário!$A:$A,A12) -> 10.28206 | I12: =IFERROR(H12/E12,0) -> 0.4150292 | J12: =IFERROR(E12/C12,0) -> 0.25279904 | K12: =IFERROR(F12/C12,0) -> 0.085467095 | L12: =IFERROR(H12/C12,0) -> 0.10491898
A13: 46245 | B13: Terça | C13: =COUNTIFS(Diário!$A:$A,A13) -> 99 | D13: =SUMIFS(Diário!$G:$G,Diário!$A:$A,A13) -> 1394 | E13: =SUMIFS(Diário!$H:$H,Diário!$A:$A,A13) -> 25.61522 | F13: =SUMIFS(Diário!$I:$I,Diário!$A:$A,A13) -> 7.9453819 | G13: =IFERROR(F13/D13,0) -> 0.0056996991 | H13: =SUMIFS(Diário!$K:$K,Diário!$A:$A,A13) -> 10.113808 | I13: =IFERROR(H13/E13,0) -> 0.39483588 | J13: =IFERROR(E13/C13,0) -> 0.25873959 | K13: =IFERROR(F13/C13,0) -> 0.080256389 | L13: =IFERROR(H13/C13,0) -> 0.10215968
A14: 46246 | B14: Quarta | C14: =COUNTIFS(Diário!$A:$A,A14) -> 102 | D14: =SUMIFS(Diário!$G:$G,Diário!$A:$A,A14) -> 1610 | E14: =SUMIFS(Diário!$H:$H,Diário!$A:$A,A14) -> 26.801655 | F14: =SUMIFS(Diário!$I:$I,Diário!$A:$A,A14) -> 9.7704167 | G14: =IFERROR(F14/D14,0) -> 0.0060685764 | H14: =SUMIFS(Diário!$K:$K,Diário!$A:$A,A14) -> 10.584306 | I14: =IFERROR(H14/E14,0) -> 0.39491239 | J14: =IFERROR(E14/C14,0) -> 0.26276132 | K14: =IFERROR(F14/C14,0) -> 0.095788403 | L14: =IFERROR(H14/C14,0) -> 0.1037677
A15: 46247 | B15: Quinta | C15: =COUNTIFS(Diário!$A:$A,A15) -> 101 | D15: =SUMIFS(Diário!$G:$G,Diário!$A:$A,A15) -> 1251 | E15: =SUMIFS(Diário!$H:$H,Diário!$A:$A,A15) -> 0 | F15: =SUMIFS(Diário!$I:$I,Diário!$A:$A,A15) -> 7.2474653 | G15: =IFERROR(F15/D15,0) -> 0.0057933333 | H15: =SUMIFS(Diário!$K:$K,Diário!$A:$A,A15) -> 0 | I15: =IFERROR(H15/E15,0) -> 0 | J15: =IFERROR(E15/C15,0) -> 0 | K15: =IFERROR(F15/C15,0) -> 0.071757083 | L15: =IFERROR(H15/C15,0) -> 0
A16: 46248 | B16: Sexta | C16: =COUNTIFS(Diário!$A:$A,A16) -> 99 | D16: =SUMIFS(Diário!$G:$G,Diário!$A:$A,A16) -> 1263 | E16: =SUMIFS(Diário!$H:$H,Diário!$A:$A,A16) -> 24.173576 | F16: =SUMIFS(Diário!$I:$I,Diário!$A:$A,A16) -> 6.244213 | G16: =IFERROR(F16/D16,0) -> 0.0049439583 | H16: =SUMIFS(Diário!$K:$K,Diário!$A:$A,A16) -> 10.280081 | I16: =IFERROR(H16/E16,0) -> 0.42526107 | J16: =IFERROR(E16/C16,0) -> 0.24417753 | K16: =IFERROR(F16/C16,0) -> 0.063072859 | L16: =IFERROR(H16/C16,0) -> 0.1038392
... A20: 46253 | B20: Quarta | C20: =COUNTIFS(Diário!$A:$A,A20) -> 97 | D20: =SUMIFS(Diário!$G:$G,Diário!$A:$A,A20) -> 1564 | E20: =SUMIFS(Diário!$H:$H,Diário!$A:$A,A20) -> 25.042512 | F20: =SUMIFS(Diário!$I:$I,Diário!$A:$A,A20) -> 8.0159722 | G20: =IFERROR(F20/D20,0) -> 0.0051253009 | H20: =SUMIFS(Diário!$K:$K,Diário!$A:$A,A20) -> 8.4410532 | I20: =IFERROR(H20/E20,0) -> 0.33706896 | J20: =IFERROR(E20/C20,0) -> 0.25817022 | K20: =IFERROR(F20/C20,0) -> 0.082638889 | L20: =IFERROR(H20/C20,0) -> 0.087021169
A21: TOTAL | C21: =ROUND(AVERAGE(C5:C20),0) -> 99 | D21: =SUM(D5:D20) -> 23493 | E21: =SUM(E5:E20) -> 371.07391 | F21: =SUM(F5:F20) -> 143.76939 | G21: =AVERAGE(G5:G20) -> 0.0060224769 | H21: =SUM(H5:H20) -> 139.45679 | I21: =IFERROR(H21/E21,0) -> 0.37581945 | J21: =SUM(J5:J20) -> 3.7588202 | K21: =SUM(K5:K20) -> 1.4357708 | L21: =SUM(L5:L20) -> 1.4168739

Sheet Faltas do Dia
B2: FALTAS DO DIA
B3: Data: | C3: 46253
B5: Total esperados (ativos): | C5: =COUNTA(B10:B125) -> 116
B6: Total FALTARAM: | C6: =COUNTIF(I10:I125,"FALTOU") -> 20
B7: Total trabalharam: | C7: =COUNTIF(I10:I125,"TRABALHOU") -> 96
B9: Agente | C9: Supervisor | D9: Coordenador | E9: Área | F9: Turno | G9: Cargo | H9: Status | I9: Logou?
B10: ADRIAM DA CONCEICAO SILVA | C10: JENNYFER CABRERA DA CRUZ LIMA | D10: KARLA DAS DORES DE SOUSA | E10: BACKOFFICE | F10: VESPERTINO | G10: OPERADOR DE TELEMARKETING II | H10: ATIVIDADE NORMAL | I10: =IF(COUNTIFS(Diário!$B:$B,B10,Diário!$A:$A,$C$3)=0,"FALTOU","TRABALHOU") -> TRABALHOU | K10: 46174
B11: ANA PAULA NASCIMENTO MONTEIRO | C11: JENNYFER CABRERA DA CRUZ LIMA | D11: KARLA DAS DORES DE SOUSA | E11: BACKOFFICE | F11: INTEGRAL | G11: OPERADOR DE TELEMARKETING II | H11: ATIVIDADE NORMAL | I11: =IF(COUNTIFS(Diário!$B:$B,B11,Diário!$A:$A,$C$3)=0,"FALTOU","TRABALHOU") -> TRABALHOU | K11: 46175
B12: CAMILA MORAIS PIERI | C12: JENNYFER CABRERA DA CRUZ LIMA | D12: KARLA DAS DORES DE SOUSA | E12: BACKOFFICE | F12: INTEGRAL | G12: OPERADOR DE TELEMARKETING II | H12: ATIVIDADE NORMAL | I12: =IF(COUNTIFS(Diário!$B:$B,B12,Diário!$A:$A,$C$3)=0,"FALTOU","TRABALHOU") -> TRABALHOU | K12: 46176
B13: DIVINA DOS REIS PEREIRA SANTOS | C13: JENNYFER CABRERA DA CRUZ LIMA | D13: KARLA DAS DORES DE SOUSA | E13: BACKOFFICE | F13: INTEGRAL | G13: OPERADOR DE TELEMARKETING II | H13: ATIVIDADE NORMAL | I13: =IF(COUNTIFS(Diário!$B:$B,B13,Diário!$A:$A,$C$3)=0,"FALTOU","TRABALHOU") -> TRABALHOU | K13: 46177
B14: EDIVANEA LIMA LUNA | C14: JENNYFER CABRERA DA CRUZ LIMA | D14: KARLA DAS DORES DE SOUSA | E14: BACKOFFICE | F14: INTEGRAL | G14: OPERADOR DE TELEMARKETING II | H14: ATIVIDADE NORMAL | I14: =IF(COUNTIFS(Diário!$B:$B,B14,Diário!$A:$A,$C$3)=0,"FALTOU","TRABALHOU") -> TRABALHOU | K14: 46178
B15: HUMBERTO FELIPE SANTANA RODRIGUES | C15: JENNYFER CABRERA DA CRUZ LIMA | D15: KARLA DAS DORES DE SOUSA | E15: BACKOFFICE | F15: INTEGRAL | G15: OPERADOR DE TELEMARKETING II | H15: ATIVIDADE NORMAL | I15: =IF(COUNTIFS(Diário!$B:$B,B15,Diário!$A:$A,$C$3)=0,"FALTOU","TRABALHOU") -> TRABALHOU | K15: 46179
B16: ISABELA MENDES DAS NEVES | C16: JENNYFER CABRERA DA CRUZ LIMA | D16: KARLA DAS DORES DE SOUSA | E16: BACKOFFICE | F16: INTEGRAL | G16: OPERADOR DE TELEMARKETING II | H16: ATIVIDADE NORMAL | I16: =IF(COUNTIFS(Diário!$B:$B,B16,Diário!$A:$A,$C$3)=0,"FALTOU","TRABALHOU") -> TRABALHOU | K16: 46181
B17: JULIANA DIAS NEVES | C17: JENNYFER CABRERA DA CRUZ LIMA | D17: KARLA DAS DORES DE SOUSA | E17: BACKOFFICE | F17: INTEGRAL | G17: OPERADOR DE TELEMARKETING II | H17: ATIVIDADE NORMAL | I17: =IF(COUNTIFS(Diário!$B:$B,B17,Diário!$A:$A,$C$3)=0,"FALTOU","TRABALHOU") -> FALTOU | K17: 46182
B18: KEILA GOMES DA COSTA NEVES DE MENDONCA | C18: JENNYFER CABRERA DA CRUZ LIMA | D18: KARLA DAS DORES DE SOUSA | E18: BACKOFFICE | F18: INTEGRAL | G18: OPERADOR DE TELEMARKETING II | H18: ATIVIDADE NORMAL | I18: =IF(COUNTIFS(Diário!$B:$B,B18,Diário!$A:$A,$C$3)=0,"FALTOU","TRABALHOU") -> TRABALHOU | K18: 46183
B19: KEMELLY CAMILO TOMAZ | C19: JENNYFER CABRERA DA CRUZ LIMA | D19: KARLA DAS DORES DE SOUSA | E19: BACKOFFICE | F19: INTEGRAL | G19: OPERADOR DE TELEMARKETING II | H19: ATIVIDADE NORMAL | I19: =IF(COUNTIFS(Diário!$B:$B,B19,Diário!$A:$A,$C$3)=0,"FALTOU","TRABALHOU") -> TRABALHOU | K19: 46184
B20: LUCAS HENRIQUE DIAS SOARES | C20: JENNYFER CABRERA DA CRUZ LIMA | D20: KARLA DAS DORES DE SOUSA | E20: BACKOFFICE | F20: MATUTINO | G20: OPERADOR DE TELEMARKETING II | H20: ATIVIDADE NORMAL | I20: =IF(COUNTIFS(Diário!$B:$B,B20,Diário!$A:$A,$C$3)=0,"FALTOU","TRABALHOU") -> TRABALHOU | K20: 46185
B21: MARIA EDUARDA CARNEIRO RIBEIRO RECO | C21: JENNYFER CABRERA DA CRUZ LIMA | D21: KARLA DAS DORES DE SOUSA | E21: BACKOFFICE | F21: INTEGRAL | G21: OPERADOR DE TELEMARKETING II | H21: ATIVIDADE NORMAL | I21: =IF(COUNTIFS(Diário!$B:$B,B21,Diário!$A:$A,$C$3)=0,"FALTOU","TRABALHOU") -> TRABALHOU | K21: 46186
B22: SOPHIA ASSIS CARDOSO | C22: JENNYFER CABRERA DA CRUZ LIMA | D22: KARLA DAS DORES DE SOUSA | E22: BACKOFFICE | F22: INTEGRAL | G22: OPERADOR DE TELEMARKETING II | H22: ATIVIDADE NORMAL | I22: =IF(COUNTIFS(Diário!$B:$B,B22,Diário!$A:$A,$C$3)=0,"FALTOU","TRABALHOU") -> TRABALHOU | K22: 46188
B23: THAYLA VITORIA LIMA DOS SANTOS | C23: JENNYFER CABRERA DA CRUZ LIMA | D23: KARLA DAS DORES DE SOUSA | E23: BACKOFFICE | F23: VESPERTINO | G23: OPERADOR DE TELEMARKETING II | H23: ATIVIDADE NORMAL | I23: =IF(COUNTIFS(Diário!$B:$B,B23,Diário!$A:$A,$C$3)=0,"FALTOU","TRABALHOU") -> TRABALHOU
B24: ZIRLENE SOUZA SILVA LOPO | C24: JENNYFER CABRERA DA CRUZ LIMA | D24: KARLA DAS DORES DE SOUSA | E24: QUALIDADE | F24: MATUTINO | G24: MONITOR | H24: ATIVIDADE NORMAL | I24: =IF(COUNTIFS(Diário!$B:$B,B24,Diário!$A:$A,$C$3)=0,"FALTOU","TRABALHOU") -> FALTOU
B25: ANA JULIA LOPES DE CASTRO | C25: MARCOS VINICIUS ALVES DE OLIVEIRA | D25: BIANCA MUNIZ FERREIRA | E25: RETENCAO | F25: MATUTINO | G25: OPERADOR DE TELEMARKETING I | H25: ATIVIDADE NORMAL | I25: =IF(COUNTIFS(Diário!$B:$B,B25,Diário!$A:$A,$C$3)=0,"FALTOU","TRABALHOU") -> TRABALHOU
B26: ANNE HELOIZA NOGUEIRA SANTOS | C26: MARCOS VINICIUS ALVES DE OLIVEIRA | D26: BIANCA MUNIZ FERREIRA | E26: RETENCAO | F26: MATUTINO | G26: OPERADOR DE TELEMARKETING I | H26: ATIVIDADE NORMAL | I26: =IF(COUNTIFS(Diário!$B:$B,B26,Diário!$A:$A,$C$3)=0,"FALTOU","TRABALHOU") -> FALTOU
B27: DANDARA MONTEIRO OLIVEIRA | C27: MARCOS VINICIUS ALVES DE OLIVEIRA | D27: BIANCA MUNIZ FERREIRA | E27: RETENCAO | F27: MATUTINO | G27: OPERADOR DE TELEMARKETING I | H27: ATIVIDADE NORMAL | I27: =IF(COUNTIFS(Diário!$B:$B,B27,Diário!$A:$A,$C$3)=0,"FALTOU","TRABALHOU") -> TRABALHOU
B28: DANILLO BARBOSA OLIVEIRA | C28: MARCOS VINICIUS ALVES DE OLIVEIRA | D28: BIANCA MUNIZ FERREIRA | E28: RETENCAO | F28: MATUTINO | G28: OPERADOR DE TELEMARKETING I | H28: ATIVIDADE NORMAL | I28: =IF(COUNTIFS(Diário!$B:$B,B28,Diário!$A:$A,$C$3)=0,"FALTOU","TRABALHOU") -> TRABALHOU
B29: DEBORA BRAGA DE MATOS AQUINO | C29: MARCOS VINICIUS ALVES DE OLIVEIRA | D29: BIANCA MUNIZ FERREIRA | E29: RETENCAO | F29: MATUTINO | G29: OPERADOR DE TELEMARKETING I | H29: ATIVIDADE NORMAL | I29: =IF(COUNTIFS(Diário!$B:$B,B29,Diário!$A:$A,$C$3)=0,"FALTOU","TRABALHOU") -> TRABALHOU
B30: FABIO BORGES DOS SANTOS FILHO | C30: MARCOS VINICIUS ALVES DE OLIVEIRA | D30: BIANCA MUNIZ FERREIRA | E30: RETENCAO | F30: MATUTINO | G30: OPERADOR DE TELEMARKETING I | H30: ATIVIDADE NORMAL | I30: =IF(COUNTIFS(Diário!$B:$B,B30,Diário!$A:$A,$C$3)=0,"FALTOU","TRABALHOU") -> FALTOU
B31: GEOVANA GABRIELLY QUEIROZ DOS SANTOS | C31: MARCOS VINICIUS ALVES DE OLIVEIRA | D31: BIANCA MUNIZ FERREIRA | E31: RETENCAO | F31: MATUTINO | G31: OPERADOR DE TELEMARKETING I | H31: ATIVIDADE NORMAL | I31: =IF(COUNTIFS(Diário!$B:$B,B31,Diário!$A:$A,$C$3)=0,"FALTOU","TRABALHOU") -> TRABALHOU
B32: IASMYM RIBEIRO DA SILVA | C32: MARCOS VINICIUS ALVES DE OLIVEIRA | D32: BIANCA MUNIZ FERREIRA | E32: RETENCAO | F32: MATUTINO | G32: OPERADOR DE TELEMARKETING I | H32: ATIVIDADE NORMAL | I32: =IF(COUNTIFS(Diário!$B:$B,B32,Diário!$A:$A,$C$3)=0,"FALTOU","TRABALHOU") -> TRABALHOU
B33: KEYTH RODRIGUES DE MORAIS | C33: MARCOS VINICIUS ALVES DE OLIVEIRA | D33: BIANCA MUNIZ FERREIRA | E33: VENDAS | F33: MATUTINO | G33: OPERADOR DE TELEMARKETING I | H33: ATIVIDADE NORMAL | I33: =IF(COUNTIFS(Diário!$B:$B,B33,Diário!$A:$A,$C$3)=0,"FALTOU","TRABALHOU") -> TRABALHOU
B34: LOISLENE OLIVEIRA DA SILVA | C34: MARCOS VINICIUS ALVES DE OLIVEIRA | D34: BIANCA MUNIZ FERREIRA | E34: RETENCAO | F34: MATUTINO | G34: OPERADOR DE TELEMARKETING I | H34: ATIVIDADE NORMAL | I34: =IF(COUNTIFS(Diário!$B:$B,B34,Diário!$A:$A,$C$3)=0,"FALTOU","TRABALHOU") -> FALTOU
... B125: RYAN FELYPE LOURENCO REGO | C125: RENATA MARQUES LIMA DOS REIS | D125: BIANCA MUNIZ FERREIRA | E125: SAC | F125: VESPERTINO | G125: OPERADOR DE TELEMARKETING I | H125: ATIVIDADE NORMAL | I125: =IF(COUNTIFS(Diário!$B:$B,B125,Diário!$A:$A,$C$3)=0,"FALTOU","TRABALHOU") -> TRABALHOU

Sheet Comparativo Sup.
A1: COMPARATIVO ENTRE SUPERVISORES
A4: Supervisor | B4: Coordenador | C4: # Agentes | D4: Chamadas | E4: Chamadas/Agente | F4: Tempo Logado | G4: TMA | H4: Tempo Pausado | I4: Pausa % Login | J4: BANHEI | K4: DESCAN | L4: LANCHE | M4: MANUAL | N4: TREINA | O4: Pausado/Agente
A5: RENATA MARQUES LIMA DOS REIS | B5: BIANCA MUNIZ FERREIRA | C5: =COUNTIF(Consolidado!$D:$D,A5) -> 16 | D5: =SUMIFS(Diário!$G:$G,Diário!$D:$D,A5) -> 5927 | E5: =IFERROR(D5/C5,0) -> 370.4375 | F5: =SUMIFS(Diário!$H:$H,Diário!$D:$D,A5) -> 56.102384 | G5: =IFERROR(SUMIFS(Diário!$I:$I,Diário!$D:$D,A5)/D5,0) -> 0.0053920602 | H5: =SUMIFS(Diário!$K:$K,Diário!$D:$D,A5) -> 17.64103 | I5: =IFERROR(H5/F5,0) -> 0.3144435 | J5: =SUMIFS(Diário!$N:$N,Diário!$D:$D,A5) -> 1.6843866 | K5: =SUMIFS(Diário!$O:$O,Diário!$D:$D,A5) -> 2.970081 | L5: =SUMIFS(Diário!$S:$S,Diário!$D:$D,A5) -> 3.0174074 | M5: =SUMIFS(Diário!$U:$U,Diário!$D:$D,A5) -> 0.41680556 | N5: =SUMIFS(Diário!$W:$W,Diário!$D:$D,A5) -> 8.5039931 | O5: =IFERROR(H5/C5,0) -> 1.1025644
A6: JENNYFER CABRERA DA CRUZ LIMA | B6: KARLA DAS DORES DE SOUSA | C6: =COUNTIF(Consolidado!$D:$D,A6) -> 14 | D6: =SUMIFS(Diário!$G:$G,Diário!$D:$D,A6) -> 83 | E6: =IFERROR(D6/C6,0) -> 5.9285714 | F6: =SUMIFS(Diário!$H:$H,Diário!$D:$D,A6) -> 49.186377 | G6: =IFERROR(SUMIFS(Diário!$I:$I,Diário!$D:$D,A6)/D6,0) -> 0.010979757 | H6: =SUMIFS(Diário!$K:$K,Diário!$D:$D,A6) -> 13.52544 | I6: =IFERROR(H6/F6,0) -> 0.27498345 | J6: =SUMIFS(Diário!$N:$N,Diário!$D:$D,A6) -> 0.85015046 | K6: =SUMIFS(Diário!$O:$O,Diário!$D:$D,A6) -> 3.3662153 | L6: =SUMIFS(Diário!$S:$S,Diário!$D:$D,A6) -> 2.0304051 | M6: =SUMIFS(Diário!$U:$U,Diário!$D:$D,A6) -> 1.549456 | N6: =SUMIFS(Diário!$W:$W,Diário!$D:$D,A6) -> 0.99984954 | O6: =IFERROR(H6/C6,0) -> 0.96610285
A7: MARCOS VINICIUS ALVES DE OLIVEIRA | B7: BIANCA MUNIZ FERREIRA | C7: =COUNTIF(Consolidado!$D:$D,A7) -> 19 | D7: =SUMIFS(Diário!$G:$G,Diário!$D:$D,A7) -> 3019 | E7: =IFERROR(D7/C7,0) -> 158.89474 | F7: =SUMIFS(Diário!$H:$H,Diário!$D:$D,A7) -> 63.281273 | G7: =IFERROR(SUMIFS(Diário!$I:$I,Diário!$D:$D,A7)/D7,0) -> 0.012894016 | H7: =SUMIFS(Diário!$K:$K,Diário!$D:$D,A7) -> 33.659421 | I7: =IFERROR(H7/F7,0) -> 0.53190177 | J7: =SUMIFS(Diário!$N:$N,Diário!$D:$D,A7) -> 2.3864468 | K7: =SUMIFS(Diário!$O:$O,Diário!$D:$D,A7) -> 3.937037 | L7: =SUMIFS(Diário!$S:$S,Diário!$D:$D,A7) -> 3.4701157 | M7: =SUMIFS(Diário!$U:$U,Diário!$D:$D,A7) -> 1.0478241 | N7: =SUMIFS(Diário!$W:$W,Diário!$D:$D,A7) -> 20.0186 | O7: =IFERROR(H7/C7,0) -> 1.7715485
A8: PAULA FERNANDA ALVES | B8: KARLA DAS DORES DE SOUSA | C8: =COUNTIF(Consolidado!$D:$D,A8) -> 13 | D8: =SUMIFS(Diário!$G:$G,Diário!$D:$D,A8) -> 2871 | E8: =IFERROR(D8/C8,0) -> 220.84615 | F8: =SUMIFS(Diário!$H:$H,Diário!$D:$D,A8) -> 43.537407 | G8: =IFERROR(SUMIFS(Diário!$I:$I,Diário!$D:$D,A8)/D8,0) -> 0.0035848264 | H8: =SUMIFS(Diário!$K:$K,Diário!$D:$D,A8) -> 7.9218519 | I8: =IFERROR(H8/F8,0) -> 0.18195507 | J8: =SUMIFS(Diário!$N:$N,Diário!$D:$D,A8) -> 1.0038194 | K8: =SUMIFS(Diário!$O:$O,Diário!$D:$D,A8) -> 2.2700694 | L8: =SUMIFS(Diário!$S:$S,Diário!$D:$D,A8) -> 2.317581 | M8: =SUMIFS(Diário!$U:$U,Diário!$D:$D,A8) -> 0.50082176 | N8: =SUMIFS(Diário!$W:$W,Diário!$D:$D,A8) -> 0.3369213 | O8: =IFERROR(H8/C8,0) -> 0.60937322
A9: REGINALDO SOUSA BARBOSA | B9: BIANCA MUNIZ FERREIRA | C9: =COUNTIF(Consolidado!$D:$D,A9) -> 8 | D9: =SUMIFS(Diário!$G:$G,Diário!$D:$D,A9) -> 2023 | E9: =IFERROR(D9/C9,0) -> 252.875 | F9: =SUMIFS(Diário!$H:$H,Diário!$D:$D,A9) -> 28.522407 | G9: =IFERROR(SUMIFS(Diário!$I:$I,Diário!$D:$D,A9)/D9,0) -> 0.0035283681 | H9: =SUMIFS(Diário!$K:$K,Diário!$D:$D,A9) -> 4.1538426 | I9: =IFERROR(H9/F9,0) -> 0.14563436 | J9: =SUMIFS(Diário!$N:$N,Diário!$D:$D,A9) -> 0.41152778 | K9: =SUMIFS(Diário!$O:$O,Diário!$D:$D,A9) -> 1.4370023 | L9: =SUMIFS(Diário!$S:$S,Diário!$D:$D,A9) -> 1.4990278 | M9: =SUMIFS(Diário!$U:$U,Diário!$D:$D,A9) -> 0.073576389 | N9: =SUMIFS(Diário!$W:$W,Diário!$D:$D,A9) -> 0.0040972222 | O9: =IFERROR(H9/C9,0) -> 0.51923032
A10: RAFAEL ALVES DE LIMA | B10: BIANCA MUNIZ FERREIRA | C10: =COUNTIF(Consolidado!$D:$D,A10) -> 24 | D10: =SUMIFS(Diário!$G:$G,Diário!$D:$D,A10) -> 7723 | E10: =IFERROR(D10/C10,0) -> 321.79167 | F10: =SUMIFS(Diário!$H:$H,Diário!$D:$D,A10) -> 78.998507 | G10: =IFERROR(SUMIFS(Diário!$I:$I,Diário!$D:$D,A10)/D10,0) -> 0.0041478009 | H10: =SUMIFS(Diário!$K:$K,Diário!$D:$D,A10) -> 26.154363 | I10: =IFERROR(H10/F10,0) -> 0.33107415 | J10: =SUMIFS(Diário!$N:$N,Diário!$D:$D,A10) -> 2.3181713 | K10: =SUMIFS(Diário!$O:$O,Diário!$D:$D,A10) -> 3.9776389 | L10: =SUMIFS(Diário!$S:$S,Diário!$D:$D,A10) -> 3.9123843 | M10: =SUMIFS(Diário!$U:$U,Diário!$D:$D,A10) -> 0.51671296 | N10: =SUMIFS(Diário!$W:$W,Diário!$D:$D,A10) -> 12.846921 | O10: =IFERROR(H10/C10,0) -> 1.0897651
A11: NICOLAS NOLBERTO MENA | B11: BIANCA MUNIZ FERREIRA | C11: =COUNTIF(Consolidado!$D:$D,A11) -> 19 | D11: =SUMIFS(Diário!$G:$G,Diário!$D:$D,A11) -> 1758 | E11: =IFERROR(D11/C11,0) -> 92.526316 | F11: =SUMIFS(Diário!$H:$H,Diário!$D:$D,A11) -> 51.445556 | G11: =IFERROR(SUMIFS(Diário!$I:$I,Diário!$D:$D,A11)/D11,0) -> 0.012803113 | H11: =SUMIFS(Diário!$K:$K,Diário!$D:$D,A11) -> 36.400845 | I11: =IFERROR(H11/F11,0) -> 0.70756054 | J11: =SUMIFS(Diário!$N:$N,Diário!$D:$D,A11) -> 1.5849074 | K11: =SUMIFS(Diário!$O:$O,Diário!$D:$D,A11) -> 3.3193634 | L11: =SUMIFS(Diário!$S:$S,Diário!$D:$D,A11) -> 2.9854861 | M11: =SUMIFS(Diário!$U:$U,Diário!$D:$D,A11) -> 19.741076 | N11: =SUMIFS(Diário!$W:$W,Diário!$D:$D,A11) -> 6.6260301 | O11: =IFERROR(H11/C11,0) -> 1.9158339
C12: =SUM(C5:C11) -> 113 | D12: =SUM(D5:D11) -> 23404 | E12: =IFERROR(D12/C12,0) -> 207.11504 | F12: =SUM(F5:F11) -> 371.07391 | H12: =SUM(H5:H11) -> 139.45679 | I12: =IFERROR(H12/F12,0) -> 0.37581945 | J12: =SUM(J5:J11) -> 10.23941 | K12: =SUM(K5:K11) -> 21.277407 | L12: =SUM(L5:L11) -> 19.232407 | M12: =SUM(M5:M11) -> 23.846273 | N12: =SUM(N5:N11) -> 49.336412 | O12: =IFERROR(H12/C12,0) -> 1.2341309

Sheet Consolidado
A1: Identificação | I1: Operação | P1: Pausas — Detalhamento (a partir de 05/05)
A2: Nome Completo | B2: ID Sistema | C2: Status | D2: Supervisor | E2: Coordenador | F2: Área | G2: Turno | H2: Cargo | I2: Dias Logados | J2: Chamadas | K2: Tempo Logado | L2: Tempo Falado | M2: TMA | N2: Tempo Pausado | O2: Pausa % Login | P2: BANHEI | Q2: DESCAN | R2: DISMX | S2: FEEDBK | T2: LAGGED | U2: LANCHE | V2: LOGIN | W2: MANUAL | X2: TESTE | Y2: TREINA
A3: ADRIAM DA CONCEICAO SILVA | B3: adriamsilva | C3: ATIVIDADE NORMAL | D3: JENNYFER CABRERA DA CRUZ LIMA | E3: KARLA DAS DORES DE SOUSA | F3: BACKOFFICE | G3: VESPERTINO | H3: OPERADOR DE TELEMARKETING II | I3: 16 | J3: 32 | K3: 3.9831019 | L3: 0.13243056 | M3: =IFERROR(L3/J3,0) -> 0.0041384491 | N3: 0.67828704 | O3: =IFERROR(N3/K3,0) -> 0.17029116 | P3: 0.13405093 | Q3: 0.21653935 | S3: 0.0071759259 | T3: 0.02181713 | U3: 0.20965278 | V3: 0.012199074 | W3: 0.0052662037 | Y3: 0.071168981
A4: ALAINE BARBOSA RIBEIRO | B4: alaineribeiro | C4: ATIVIDADE NORMAL | D4: RAFAEL ALVES DE LIMA | E4: BIANCA MUNIZ FERREIRA | F4: SAC | G4: MATUTINO | H4: OPERADOR DE TELEMARKETING I | I4: 16 | J4: 273 | K4: 3.8627662 | L4: 2.1213542 | M4: =IFERROR(L4/J4,0) -> 0.0077705324 | N4: 0.65849537 | O4: =IFERROR(N4/K4,0) -> 0.17047249 | P4: 0.088703704 | Q4: 0.22506944 | R4: 0.011319444 | S4: 0.086770833 | T4: 0.013773148 | U4: 0.18393519 | V4: 0.018541667 | W4: 0.029826389
A5: ALEXANDRE LOPES DOS SANTOS | B5: alexandresantos | C5: ATIVIDADE NORMAL | D5: REGINALDO SOUSA BARBOSA | E5: KARLA DAS DORES DE SOUSA | F5: COBRANCA | G5: VESPERTINO | H5: OPERADOR DE TELEMARKETING I | I5: 16 | J5: 273 | K5: 3.9175694 | L5: 1.0278356 | M5: =IFERROR(L5/J5,0) -> 0.0037649653 | N5: 0.51260417 | O5: =IFERROR(N5/K5,0) -> 0.1308475 | P5: 0.030729167 | Q5: 0.16796296 | S5: 0.044155093 | T5: 0.04875 | U5: 0.21070602 | V5: 0.0041782407 | W5: 0.0053356481
A6: AMANDA LORENA ALVES | B6: amandaalves | C6: ATIVIDADE NORMAL | D6: RAFAEL ALVES DE LIMA | E6: BIANCA MUNIZ FERREIRA | F6: SAC | G6: MATUTINO | H6: OPERADOR DE TELEMARKETING I | I6: 11 | J6: 362 | K6: 2.6003935 | L6: 1.3334606 | M6: =IFERROR(L6/J6,0) -> 0.003683588 | N6: 0.44761574 | O6: =IFERROR(N6/K6,0) -> 0.17213385 | P6: 0.022638889 | Q6: 0.1475 | S6: 0.0109375 | T6: 0.012592593 | U6: 0.13996528 | V6: 0.097291667 | W6: 0.0041550926 | Y6: 0.012048611
A7: ANANDA SANTOS VIEIRA | B7: anandavieira | C7: ATIVIDADE NORMAL | D7: RAFAEL ALVES DE LIMA | E7: BIANCA MUNIZ FERREIRA | F7: SAC | G7: MATUTINO | H7: OPERADOR DE TELEMARKETING I | I7: 13 | J7: 419 | K7: 2.9790625 | L7: 1.4293981 | M7: =IFERROR(L7/J7,0) -> 0.0034114468 | N7: 0.51721065 | O7: =IFERROR(N7/K7,0) -> 0.17361524 | P7: 0.097372685 | Q7: 0.15001157 | R7: 0.0019791667 | S7: 0.014849537 | T7: 0.007650463 | U7: 0.14467593 | V7: 0.086527778 | W7: 0.0042476852 | Y7: 0.0092476852
A8: ANDRESSA PEREIRA DOS SANTOS | B8: andressasantos | C8: ATIVIDADE NORMAL | D8: RAFAEL ALVES DE LIMA | E8: BIANCA MUNIZ FERREIRA | F8: SAC | G8: MATUTINO | H8: OPERADOR DE TELEMARKETING I | I8: 16 | J8: 521 | K8: 3.8572222 | L8: 1.84625 | M8: =IFERROR(L8/J8,0) -> 0.003543669 | N8: 0.67732639 | O8: =IFERROR(N8/K8,0) -> 0.17559952 | P8: 0.056655093 | Q8: 0.20424769 | S8: 0.0159375 | U8: 0.2025 | V8: 0.066099537 | W8: 0.076527778 | Y8: 0.048090278
A9: ARIENE GONCALVES DE MORAES NASCIMENTO | B9: arienenascimento | C9: ATIVIDADE NORMAL | D9: RAFAEL ALVES DE LIMA | E9: BIANCA MUNIZ FERREIRA | F9: SAC | G9: MATUTINO | H9: OPERADOR DE TELEMARKETING I | I9: 13 | J9: 62 | K9: 2.8863079 | L9: 0.25439815 | M9: =IFERROR(L9/J9,0) -> 0.0041031944 | N9: 2.4881944 | O9: =IFERROR(N9/K9,0) -> 0.86206827 | P9: 0.22663194 | Q9: 0.17446759 | U9: 0.079282407 | V9: 0.44087963 | W9: 0.0052777778 | Y9: 1.5615625
A10: BARBARA GLENDA DONIZETE DIAS | B10: barbaradias | C10: ATIVIDADE NORMAL | D10: RAFAEL ALVES DE LIMA | E10: BIANCA MUNIZ FERREIRA | F10: SAC | G10: MATUTINO | H10: OPERADOR DE TELEMARKETING I | I10: 16 | J10: 22 | K10: 3.4550347 | L10: 0.07974537 | M10: =IFERROR(L10/J10,0) -> 0.0036247917 | N10: 3.2852199 | O10: =IFERROR(N10/K10,0) -> 0.95085004 | Q10: 0.088043981 | U10: 0.14774306 | V10: 0.010555556 | W10: 0.00023148148 | Y10: 3.0386458
A11: BRENDO ARAUJO DA LUZ | B11: brendoluz | C11: ATIVIDADE NORMAL | D11: NICOLAS NOLBERTO MENA | E11: BIANCA MUNIZ FERREIRA | F11: RETENCAO | G11: VESPERTINO | H11: OPERADOR DE TELEMARKETING I | I11: 16 | J11: 111 | K11: 3.3726273 | L11: 1.7493981 | M11: =IFERROR(L11/J11,0) -> 0.015760347 | N11: 2.3576736 | O11: =IFERROR(N11/K11,0) -> 0.69906141 | P11: 0.0041898148 | Q11: 0.18739583 | S11: 0.031828704 | U11: 0.18415509 | V11: 0.039525463 | W11: 1.6025926 | Y11: 0.30797454
A12: CAMILA OLIVEIRA DAS CHAGAS | B12: camilachagas | C12: ATIVIDADE NORMAL | D12: NICOLAS NOLBERTO MENA | E12: BIANCA MUNIZ FERREIRA | F12: RETENCAO | G12: VESPERTINO | H12: OPERADOR DE TELEMARKETING I | I12: 16 | J12: 90 | K12: 3.3141088 | L12: 1.3918056 | M12: =IFERROR(L12/J12,0) -> 0.015464502 | N12: 2.4498843 | O12: =IFERROR(N12/K12,0) -> 0.73922868 | P12: 0.058726852 | Q12: 0.30449074 | S12: 0.094594907 | U12: 0.25184028 | V12: 0.030601852 | W12: 1.2009606 | Y12: 0.50861111
A13: CARLA RAYNARA CAMPELO COSTA | B13: carlacampelo | C13: ATIVIDADE NORMAL | D13: PAULA FERNANDA ALVES | E13: KARLA DAS DORES DE SOUSA | F13: COBRANCA | G13: MATUTINO | H13: OPERADOR DE TELEMARKETING I | I13: 12 | J13: 276 | K13: 2.9303704 | L13: 0.62780093 | M13: =IFERROR(L13/J13,0) -> 0.0022746412 | N13: 0.41563657 | O13: =IFERROR(N13/K13,0) -> 0.14183756 | P13: 0.01025463 | Q13: 0.1490162 | R13: 0.011296296 | S13: 0.03224537 | T13: 0.00011574074 | U13: 0.15699074 | V13: 0.0018518519 | W13: 0.0027662037 | Y13: 0.050659722
A14: DAIANE FERREIRA DA SILVA | B14: daianesilva | C14: ATIVIDADE NORMAL | D14: PAULA FERNANDA ALVES | E14: KARLA DAS DORES DE SOUSA | F14: COBRANCA | G14: MATUTINO | H14: OPERADOR DE TELEMARKETING I | I14: 15 | J14: 274 | K14: 3.6674653 | L14: 0.6462037 | M14: =IFERROR(L14/J14,0) -> 0.0023584028 | N14: 0.53194444 | O14: =IFERROR(N14/K14,0) -> 0.14504417 | P14: 0.062476852 | Q14: 0.15336806 | R14: 0.00125 | S14: 0.0828125 | U14: 0.19722222 | V14: 0.010023148 | W14: 0.015856481 | Y14: 0.0074421296
A15: DANDARA MONTEIRO OLIVEIRA | B15: dandaraoliveira | C15: ATIVIDADE NORMAL | D15: MARCOS VINICIUS ALVES DE OLIVEIRA | E15: BIANCA MUNIZ FERREIRA | F15: RETENCAO | G15: MATUTINO | H15: OPERADOR DE TELEMARKETING I | I15: 16 | J15: 104 | K15: 3.4274884 | L15: 2.0933912 | M15: =IFERROR(L15/J15,0) -> 0.020128762 | N15: 1.9389699 | O15: =IFERROR(N15/K15,0) -> 0.56571158 | P15: 0.27946759 | Q15: 0.26173611 | R15: 0.034791667 | S15: 0.012303241 | U15: 0.17681713 | V15: 0.061782407 | W15: 0.063773148 | Y15: 1.0482292
A16: DANILLO BARBOSA OLIVEIRA | B16: danillooliveira | C16: ATIVIDADE NORMAL | D16: MARCOS VINICIUS ALVES DE OLIVEIRA | E16: BIANCA MUNIZ FERREIRA | F16: RETENCAO | G16: MATUTINO | H16: OPERADOR DE TELEMARKETING I | I16: 15 | J16: 185 | K16: 3.3804398 | L16: 2.3092014 | M16: =IFERROR(L16/J16,0) -> 0.012482164 | N16: 1.818831 | O16: =IFERROR(N16/K16,0) -> 0.53804567 | P16: 0.13402778 | Q16: 0.19626157 | S16: 0.0049652778 | T16: 4.6296296e-05 | U16: 0.19091435 | V16: 0.017094907 | W16: 0.014305556 | Y16: 1.2609838
A17: DEBORA BRAGA DE MATOS AQUINO | B17: deboraaquino | C17: ATIVIDADE NORMAL | D17: MARCOS VINICIUS ALVES DE OLIVEIRA | E17: BIANCA MUNIZ FERREIRA | F17: RETENCAO | G17: MATUTINO | H17: OPERADOR DE TELEMARKETING I | I17: 16 | J17: 160 | K17: 3.5322222 | L17: 2.0902083 | M17: =IFERROR(L17/J17,0) -> 0.013063796 | N17: 2.1564468 | O17: =IFERROR(N17/K17,0) -> 0.6105071 | P17: 0.11037037 | Q17: 0.21394676 | S17: 0.031863426 | U17: 0.22179398 | V17: 0.57797454 | W17: 0.010069444 | Y17: 0.99042824
A18: DEBORA DA SILVA COELHO | B18: deboracoelho | C18: ATIVIDADE NORMAL | D18: RENATA MARQUES LIMA DOS REIS | E18: BIANCA MUNIZ FERREIRA | F18: SAC | G18: VESPERTINO | H18: OPERADOR DE TELEMARKETING I | I18: 16 | J18: 483 | K18: 3.9040856 | L18: 2.7789583 | M18: =IFERROR(L18/J18,0) -> 0.0057535417 | N18: 0.56603009 | O18: =IFERROR(N18/K18,0) -> 0.14498404 | P18: 0.025046296 | Q18: 0.20891204 | S18: 0.042592593 | T18: 0.0095833333 | U18: 0.21503472 | V18: 0.011423611 | W18: 0.036388889 | Y18: 0.014490741
A19: DIOVANIA ROCHA ALVES SANTOS | B19: diovaniasantos | C19: ATIVIDADE NORMAL | D19: RAFAEL ALVES DE LIMA | E19: BIANCA MUNIZ FERREIRA | F19: SAC | G19: MATUTINO | H19: OPERADOR DE TELEMARKETING I | I19: 16 | J19: 24 | K19: 3.3416667 | L19: 0.1478588 | M19: =IFERROR(L19/J19,0) -> 0.006160787 | N19: 3.0640278 | O19: =IFERROR(N19/K19,0) -> 0.91691604 | P19: 0.22606481 | Q19: 0.17875 | U19: 0.20303241 | V19: 0.077708333 | W19: 0.00032407407 | Y19: 2.3781481
A20: EDUARDO BARBOSA MARQUES | B20: eduardomarques | C20: ATIVIDADE NORMAL | D20: PAULA FERNANDA ALVES | E20: KARLA DAS DORES DE SOUSA | F20: COBRANCA | G20: MATUTINO | H20: OPERADOR DE TELEMARKETING I | I20: 15 | J20: 242 | K20: 3.5725 | L20: 0.61115741 | M20: =IFERROR(L20/J20,0) -> 0.0025254398 | N20: 0.86340278 | O20: =IFERROR(N20/K20,0) -> 0.24168027 | P20: 0.13224537 | Q20: 0.22792824 | S20: 0.20462963 | T20: 9.2592593e-05 | U20: 0.19273148 | V20: 0.010856481 | W20: 0.0478125 | Y20: 0.044479167
A21: EDUARDO GABRIEL ANGELIM GONCALVES | B21: eduardogoncalves | C21: TREINAMENTO | D21: RENATA MARQUES LIMA DOS REIS | E21: BIANCA MUNIZ FERREIRA | F21: SAC | G21: VESPERTINO | H21: OPERADOR DE TELEMARKETING I | I21: 16 | J21: 531 | K21: 3.928287 | L21: 2.9965394 | M21: =IFERROR(L21/J21,0) -> 0.005643206 | N21: 0.55922454 | O21: =IFERROR(N21/K21,0) -> 0.14235837 | P21: 0.073298611 | Q21: 0.19299769 | S21: 0.025578704 | T21: 0.0020601852 | U21: 0.19773148 | V21: 0.022476852 | W21: 0.023900463 | Y21: 0.018518519
A22: EDYNAYANE LIMA DE FRANCA | B22: edynayanefranca | C22: ATIVIDADE NORMAL | D22: RAFAEL ALVES DE LIMA | E22: BIANCA MUNIZ FERREIRA | F22: SAC | G22: MATUTINO | H22: OPERADOR DE TELEMARKETING I | I22: 16 | J22: 597 | K22: 3.8137731 | L22: 1.7357407 | M22: =IFERROR(L22/J22,0) -> 0.0029074421 | N22: 0.80677083 | O22: =IFERROR(N22/K22,0) -> 0.21154138 | P22: 0.1247338 | Q22: 0.19605324 | S22: 0.0053703704 | U22: 0.20001157 | V22: 0.14849537 | W22: 0.059444444 | Y22: 0.072581019
A23: ELAINE OLIVEIRA SILVA | B23: elainesilva | C23: ATIVIDADE NORMAL | D23: RENATA MARQUES LIMA DOS REIS | E23: BIANCA MUNIZ FERREIRA | F23: SAC | G23: VESPERTINO | H23: OPERADOR DE TELEMARKETING I | I23: 16 | J23: 511 | K23: 3.9381713 | L23: 2.6158565 | M23: =IFERROR(L23/J23,0) -> 0.0051190972 | N23: 0.53556713 | O23: =IFERROR(N23/K23,0) -> 0.13599386 | P23: 0.041412037 | Q23: 0.21318287 | S23: 0.017905093 | U23: 0.19696759 | V23: 0.0025231481 | W23: 0.030613426 | Y23: 0.031921296
A24: FABIO BORGES DOS SANTOS FILHO | B24: fabiofilho | C24: ATIVIDADE NORMAL | D24: MARCOS VINICIUS ALVES DE OLIVEIRA | E24: BIANCA MUNIZ FERREIRA | F24: RETENCAO | G24: MATUTINO | H24: OPERADOR DE TELEMARKETING I | I24: 14 | J24: 72 | K24: 2.8712731 | L24: 1.3533796 | M24: =IFERROR(L24/J24,0) -> 0.018796944 | N24: 1.8890625 | O24: =IFERROR(N24/K24,0) -> 0.65791807 | P24: 0.23050926 | Q24: 0.23585648 | R24: 0.015081019 | T24: 0.015763889 | U24: 0.18054398 | V24: 0.072685185 | W24: 0.013576389 | Y24: 1.125
A25: GABRIELA PIRES DOS SANTOS | B25: gabrielasantos | C25: ATIVIDADE NORMAL | D25: PAULA FERNANDA ALVES | E25: KARLA DAS DORES DE SOUSA | F25: COBRANCA | G25: MATUTINO | H25: OPERADOR DE TELEMARKETING I | I25: 16 | J25: 185 | K25: 3.6265046 | L25: 0.80563657 | M25: =IFERROR(L25/J25,0) -> 0.0043547917 | N25: 0.90858796 | O25: =IFERROR(N25/K25,0) -> 0.25054096 | P25: 0.1359838 | Q25: 0.22409722 | R25: 0.058275463 | S25: 0.16347222 | T25: 0.00016203704 | U25: 0.20128472 | V25: 0.016331019 | W25: 0.016064815 | Y25: 0.09244213
A26: GEOVANA DANIELE PINTO DAS NEVES | B26: geovananeves | C26: ATIVIDADE NORMAL | D26: RAFAEL ALVES DE LIMA | E26: BIANCA MUNIZ FERREIRA | F26: SAC | G26: MATUTINO | H26: OPERADOR DE TELEMARKETING I | I26: 16 | J26: 468 | K26: 3.7658218 | L26: 1.7146875 | M26: =IFERROR(L26/J26,0) -> 0.0036638657 | N26: 0.70890046 | O26: =IFERROR(N26/K26,0) -> 0.18824589 | P26: 0.115625 | Q26: 0.1840162 | R26: 0.0013541667 | S26: 0.1158912 | T26: 0.0074768519 | U26: 0.19434028 | V26: 0.047280093 | W26: 0.0018055556 | Y26: 0.041030093
A27: GEOVANA GABRIELLY QUEIROZ DOS SANTOS | B27: geovanasantos | C27: ATIVIDADE NORMAL | D27: MARCOS VINICIUS ALVES DE OLIVEIRA | E27: BIANCA MUNIZ FERREIRA | F27: RETENCAO | G27: MATUTINO | H27: OPERADOR DE TELEMARKETING I | I27: 15 | J27: 137 | K27: 3.5774306 | L27: 2.1715972 | M27: =IFERROR(L27/J27,0) -> 0.015851076 | N27: 1.9366088 | O27: =IFERROR(N27/K27,0) -> 0.54134071 | P27: 0.076446759 | Q27: 0.18986111 | S27: 0.039328704 | U27: 0.19748843 | V27: 0.010821759 | W27: 0.17366898 | Y27: 1.2489583
A28: GERLAINY CRISTINA DE OLIVEIRA SANTOS | B28: gerlainysantos | C28: TREINAMENTO | D28: RENATA MARQUES LIMA DOS REIS | E28: BIANCA MUNIZ FERREIRA | F28: SAC | G28: VESPERTINO | H28: OPERADOR DE TELEMARKETING I | I28: 11 | J28: 260 | K28: 2.6086227 | L28: 1.8560532 | M28: =IFERROR(L28/J28,0) -> 0.007138669 | N28: 0.5053125 | O28: =IFERROR(N28/K28,0) -> 0.19370854 | P28: 0.073090278 | Q28: 0.16041667 | S28: 0.067002315 | U28: 0.15457176 | V28: 0.026736111 | W28: 0.0054861111 | Y28: 0.017731481
A29: GILIELLE MAIANE ROSA E SILVA | B29: giliellesilva | C29: ATIVIDADE NORMAL | D29: RAFAEL ALVES DE LIMA | E29: BIANCA MUNIZ FERREIRA | F29: SAC | G29: MATUTINO | H29: OPERADOR DE TELEMARKETING I | I29: 12 | J29: 451 | K29: 3.3754977 | L29: 1.5644097 | M29: =IFERROR(L29/J29,0) -> 0.0034687616 | N29: 0.6 | O29: =IFERROR(N29/K29,0) -> 0.17775157 | P29: 0.085219907 | Q29: 0.16952546 | R29: 0.003275463 | S29: 0.027881944 | T29: 0.0021990741 | U29: 0.15565972 | V29: 0.10076389 | W29: 0.0015162037 | Y29: 0.053935185
A30: GUSTAVO PEREIRA TEIXEIRA | B30: gustavoteixeira | C30: ATIVIDADE NORMAL | D30: RENATA MARQUES LIMA DOS REIS | E30: BIANCA MUNIZ FERREIRA | F30: SAC | G30: VESPERTINO | H30: OPERADOR DE TELEMARKETING I | I30: 16 | J30: 78 | K30: 3.2276736 | L30: 0.45917824 | M30: =IFERROR(L30/J30,0) -> 0.0058868981 | N30: 2.83125 | O30: =IFERROR(N30/K30,0) -> 0.87717977 | P30: 0.2156713 | Q30: 0.14755787 | S30: 0.0048032407 | U30: 0.16671296 | V30: 0.030902778 | W30: 0.011134259 | Y30: 2.2544329
A31: HELENA VITORIA MACEDO DUTRA | B31: helenadutra | C31: ATIVIDADE NORMAL | D31: RAFAEL ALVES DE LIMA | E31: BIANCA MUNIZ FERREIRA | F31: SAC | G31: MATUTINO | H31: OPERADOR DE TELEMARKETING I | I31: 15 | J31: 412 | K31: 3.8716551 | L31: 2.4536806 | M31: =IFERROR(L31/J31,0) -> 0.0059555324 | N31: 0.25055556 | O31: =IFERROR(N31/K31,0) -> 0.064715361 | Q31: 0.052974537 | S31: 0.035219907 | U31: 0.083865741 | V31: 0.0032060185 | W31: 0.029641204 | Y31: 0.043877315
A32: IASMYM RIBEIRO DA SILVA | B32: iasmymsilva | C32: ATIVIDADE NORMAL | D32: MARCOS VINICIUS ALVES DE OLIVEIRA | E32: BIANCA MUNIZ FERREIRA | F32: RETENCAO | G32: MATUTINO | H32: OPERADOR DE TELEMARKETING I | I32: 16 | J32: 156 | K32: 3.6472338 | L32: 2.1154167 | M32: =IFERROR(L32/J32,0) -> 0.013560359 | N32: 1.9593056 | O32: =IFERROR(N32/K32,0) -> 0.53720317 | P32: 0.15980324 | Q32: 0.19193287 | R32: 0.029386574 | S32: 0.019027778 | U32: 0.21320602 | V32: 0.17122685 | W32: 0.19055556 | Y32: 0.98280093
A33: ISABELA MENDES DAS NEVES | B33: isabelaneves | C33: ATIVIDADE NORMAL | D33: JENNYFER CABRERA DA CRUZ LIMA | E33: KARLA DAS DORES DE SOUSA | F33: BACKOFFICE | G33: INTEGRAL | H33: OPERADOR DE TELEMARKETING II | I33: 14 | J33: 6 | K33: 4.2203704 | L33: 0.28549769 | M33: =IFERROR(L33/J33,0) -> 0.047582951 | N33: 0.14456019 | O33: =IFERROR(N33/K33,0) -> 0.034252962 | Q33: 0.0036458333 | T33: 0.09630787 | V33: 0.0028819444 | W33: 0.041354167
A34: IVONEIDE DUARTE FERREIRA | B34: ivoneideferreira | C34: ATIVIDADE NORMAL | D34: REGINALDO SOUSA BARBOSA | E34: KARLA DAS DORES DE SOUSA | F34: COBRANCA | G34: VESPERTINO | H34: OPERADOR DE TELEMARKETING I | I34: 16 | J34: 292 | K34: 4.0258565 | L34: 1.1602315 | M34: =IFERROR(L34/J34,0) -> 0.0039733912 | N34: 0.50480324 | O34: =IFERROR(N34/K34,0) -> 0.12539027 | P34: 0.022303241 | Q34: 0.19388889 | S34: 0.059375 | T34: 0.0053819444 | U34: 0.21488426 | V34: 0.0041203704 | W34: 0.0045601852
A35: JAMILLY SALES MOTA | B35: jamillymota | C35: TREINAMENTO | D35: RENATA MARQUES LIMA DOS REIS | E35: BIANCA MUNIZ FERREIRA | F35: SAC | G35: VESPERTINO | H35: OPERADOR DE TELEMARKETING I | I35: 16 | J35: 430 | K35: 3.8220255 | L35: 2.7168171 | M35: =IFERROR(L35/J35,0) -> 0.0063181829 | N35: 0.6665162 | O35: =IFERROR(N35/K35,0) -> 0.17438822 | P35: 0.11429398 | Q35: 0.21168981 | S35: 0.032534722 | T35: 0.027962963 | U35: 0.21313657 | V35: 0.012418981 | W35: 0.035104167 | Y35: 0.018425926
A36: JENNYFER LAIS MATOS LIMA | B36: jennyferlima | C36: ATIVIDADE NORMAL | D36: RENATA MARQUES LIMA DOS REIS | E36: BIANCA MUNIZ FERREIRA | F36: SAC | G36: VESPERTINO | H36: OPERADOR DE TELEMARKETING I | I36: 16 | J36: 66 | K36: 3.4265741 | L36: 0.41209491 | M36: =IFERROR(L36/J36,0) -> 0.0062438657 | N36: 3.0744676 | O36: =IFERROR(N36/K36,0) -> 0.89724241 | P36: 0.066157407 | Q36: 0.19840278 | S36: 0.030277778 | U36: 0.19733796 | V36: 0.013865741 | W36: 0.021180556 | Y36: 2.5472222
